<?xml version="1.0"?>
<robot xmlns:xacro="http://www.ros.org/wiki/xacro">
    <!-- Base Link -->
    <link name="base_link">
        <visual>
            <geometry>
                <box size="0.05 0.05 0.05"/>
            </geometry>
        </visual>
        <collision>
            <geometry>
                <box size="0.05 0.05 0.05"/>
            </geometry>
        </collision>
    </link>

    <!-- Joint 1 -->
    <joint name="joint1" type="revolute">
        <origin xyz="0 0 0.2848" rpy="-${pi/2} 0 0"/>
        <parent link="base_link"/>
        <child link="link1"/>
        <axis xyz="0 1 0"/>
        <limit lower="-3.1415" upper="3.1415" effort="100" velocity="1"/>
    </joint>
    <link name="link1">
        <visual>
            <geometry>
                <cylinder length="0.2" radius="0.02"/>
            </geometry>
        </visual>
        <collision>
            <geometry>
                <cylinder length="0.2" radius="0.02"/>
            </geometry>
        </collision>
    </link>

    <!-- Joint 2 -->
    <joint name="joint2" type="revolute">
        <origin xyz="0 0 0" rpy="${pi/2} 0 0"/>
        <parent link="link1"/>
        <child link="link2"/>
        <axis xyz="0 1 0"/>
        <limit lower="-3.1415" upper="3.1415" effort="100" velocity="1"/>
    </joint>
    <link name="link2">
        <visual>
            <geometry>
                <cylinder length="0.2" radius="0.02"/>
            </geometry>
        </visual>
        <collision>
            <geometry>
                <cylinder length="0.2" radius="0.02"/>
            </geometry>
        </collision>
    </link>

    <!-- Joint 3 -->
    <joint name="joint3" type="revolute">
        <origin xyz="0 0 0.2420" rpy="-${pi/2} 0 0"/>
        <parent link="link2"/>
        <child link="link3"/>
        <axis xyz="0 1 0"/>
        <limit lower="-3.1415" upper="3.1415" effort="100" velocity="1"/>
    </joint>
    <link name="link3">
        <visual>
            <geometry>
                <cylinder length="0.25" radius="0.02"/> <!-- Updated length to 0.25 to match the corrected DH parameters -->
            </geometry>
        </visual>
        <collision>
            <geometry>
                <cylinder length="0.25" radius="0.02"/>
            </geometry>
        </collision>
    </link>

    <!-- Joint 4 -->
    <joint name="joint4" type="revolute">
        <origin xyz="0 0 0" rpy="${pi/2} 0 0"/>
        <parent link="link3"/>
        <child link="link4"/>
        <axis xyz="0 1 0"/>
        <limit lower="-3.1415" upper="3.1415" effort="100" velocity="1"/>
    </joint>
    <link name="link4">
        <visual>
            <geometry>
                <cylinder length="0.2" radius="0.02"/>
            </geometry>
        </visual>
        <collision>
            <geometry>
                <cylinder length="0.2" radius="0.02"/>
            </geometry>
        </collision>
    </link>

    <!-- Joint 5 -->
    <joint name="joint5" type="revolute">
        <origin xyz="0 0 0.2160" rpy="-${pi/2} 0 0"/>
        <parent link="link4"/>
        <child link="link5"/>
        <axis xyz="0 1 0"/>
        <limit lower="-3.1415" upper="3.1415" effort="100" velocity="1"/>
    </joint>
    <link name="link5">
        <visual>
            <geometry>
                <cylinder length="0.2" radius="0.02"/> <!-- Length remains as per default since it's not specified in the DH table -->
            </geometry>
        </visual>
        <collision>
            <geometry>
                <cylinder length="0.2" radius="0.02"/>
            </geometry>
        </collision>
    </link>

    <!-- Joint 6 -->
    <joint name="joint6" type="revolute">
        <origin xyz="0 0 0" rpy="${pi/2} 0 0"/>
        <parent link="link5"/>
        <child link="link6"/>
        <axis xyz="0 1 0"/>
        <limit lower="-3.1415" upper="3.1415" effort="100" velocity="1"/>
    </joint>
    <link name="link6">
        <visual>
            <geometry>
                <cylinder length="0.15" radius="0.02"/> <!-- Updated length to 0.15 to match DH parameter for d -->
            </geometry>
        </visual>
        <collision>
            <geometry>
                <cylinder length="0.15" radius="0.02"/>
            </geometry>
        </collision>
    </link>

    <!-- Joint 7 (Wrist) -->
    <joint name="joint7" type="revolute">
        <origin xyz="0 0 0.10593" rpy="0 0 0"/>
        <parent link="link6"/>
        <child link="hand_link"/>
        <axis xyz="0 1 0"/>
        <limit lower="-3.1415" upper="3.1415" effort="100" velocity="1"/>
    </joint>
    <link name="hand_link">
        <visual>
            <geometry>
                <sphere radius="0.05"/>
            </geometry>
        </visual>
        <collision>
            <geometry>
                <sphere radius="0.05"/>
            </geometry>
        </collision>
    </link>
</robot>

